<?xml version="1.0" ?>

<robot name="quadcopter">

  <material name="arches-blue">
    <color rgba="0.0 0.6235294117647059 0.8313725490196079 1" />
  </material>

  <link name="core">
    <inertial>
      <origin rpy="0 0 0" xyz="0 0 0"/>
      <mass value="0.1"/>
      <inertia ixx="0.002166" ixy="0.0" ixz="0.0" iyy="0.002166" iyz="0.0" izz="0.0041666"/>
    </inertial>
    <visual>
      <origin rpy="0 0 0" xyz="0 0 0"/>
      <geometry>
        <mesh filename="cube.stl" scale="0.5 0.5 0.1"/>
      </geometry>
      <material name="arches-blue"/>
    </visual>
    <collision>
      <origin rpy="0 0 0" xyz="0 0 0"/>
      <geometry>
        <mesh filename="cube.stl" scale="0.5 0.5 0.1"/>
      </geometry>
    </collision>
  </link>

  <link name="spar1">
    <inertial>
      <origin rpy="0 0 0" xyz="0 0 0"/>
      <mass value="0"/>
      <inertia ixx="0" ixy="0" ixz="0" iyy="0" iyz="0" izz="0"/>
    </inertial>
    <visual>
      <origin rpy="0 0 0" xyz="0 0 0"/>
      <geometry>
        <mesh filename="cylinder.stl" scale="0.075 0.075 0.75"/>
      </geometry>
      <material name="arches-blue"/>
    </visual>
    <collision>
      <origin rpy="0 0 0" xyz="0 0 0"/>
      <geometry>
        <mesh filename="cylinder.stl" scale="0.075 0.075 0.75"/>
      </geometry>
    </collision>
  </link>
  
  <link name="spar2">
    <inertial>
      <origin rpy="0 0 0" xyz="0 0 0"/>
      <mass value="0"/>
      <inertia ixx="0" ixy="0" ixz="0" iyy="0" iyz="0" izz="0"/>
    </inertial>
    <visual>
      <origin rpy="0 0 0" xyz="0 0 0"/>
      <geometry>
        <mesh filename="cylinder.stl" scale="0.075 0.075 0.75"/>
      </geometry>
      <material name="arches-blue"/>
    </visual>
    <collision>
      <origin rpy="0 0 0" xyz="0 0 0"/>
      <geometry>
        <mesh filename="cylinder.stl" scale="0.075 0.075 0.75"/>
      </geometry>
    </collision>
  </link>
  
  <link name="spar3">
    <inertial>
      <origin rpy="0 0 0" xyz="0 0 0"/>
      <mass value="0"/>
      <inertia ixx="0" ixy="0" ixz="0" iyy="0" iyz="0" izz="0"/>
    </inertial>
    <visual>
      <origin rpy="0 0 0" xyz="0 0 0"/>
      <geometry>
        <mesh filename="cylinder.stl" scale="0.075 0.075 0.75"/>
      </geometry>
      <material name="arches-blue"/>
    </visual>
    <collision>
      <origin rpy="0 0 0" xyz="0 0 0"/>
      <geometry>
        <mesh filename="cylinder.stl" scale="0.075 0.075 0.75"/>
      </geometry>
    </collision>
  </link>
  
  <link name="spar4">
    <inertial>
      <origin rpy="0 0 0" xyz="0 0 0"/>
      <mass value="0"/>
      <inertia ixx="0" ixy="0" ixz="0" iyy="0" iyz="0" izz="0"/>
    </inertial>
    <visual>
      <origin rpy="0 0 0" xyz="0 0 0"/>
      <geometry>
        <mesh filename="cylinder.stl" scale="0.075 0.075 0.75"/>
      </geometry>
      <material name="arches-blue"/>
    </visual>
    <collision>
      <origin rpy="0 0 0" xyz="0 0 0"/>
      <geometry>
        <mesh filename="cylinder.stl" scale="0.075 0.075 0.75"/>
      </geometry>
    </collision>
  </link>
  
  <link name="rotor1">
    <inertial>
      <origin rpy="0 0 0" xyz="0 0 0"/>
      <mass value="0.1"/>
      <inertia ixx="0.01414583" ixy="0" ixz="0" iyy="0.01414583" iyz="0" izz="0.028125"/>
    </inertial>
    <visual>
      <origin rpy="0 0 0" xyz="0 0 0"/>
      <geometry>
        <mesh filename="cylinder.stl" scale="0.75 0.75 0.1"/>
      </geometry>
      <material name="arches-blue"/>
    </visual>
    <collision>
      <origin rpy="0 0 0" xyz="0 0 0"/>
      <geometry>
        <mesh filename="cylinder.stl" scale="0.75 0.75 0.1"/>
      </geometry>
    </collision>
  </link>
  
  <link name="rotor2">
    <inertial>
      <origin rpy="0 0 0" xyz="0 0 0"/>
      <mass value="0.1"/>
      <inertia ixx="0.01414583" ixy="0" ixz="0" iyy="0.01414583" iyz="0" izz="0.028125"/>
    </inertial>
    <visual>
      <origin rpy="0 0 0" xyz="0 0 0"/>
      <geometry>
        <mesh filename="cylinder.stl" scale="0.75 0.75 0.1"/>
      </geometry>
      <material name="arches-blue"/>
    </visual>
    <collision>
      <origin rpy="0 0 0" xyz="0 0 0"/>
      <geometry>
        <mesh filename="cylinder.stl" scale="0.75 0.75 0.1"/>
      </geometry>
    </collision>
  </link>
  
  <link name="rotor3">
    <inertial>
      <origin rpy="0 0 0" xyz="0 0 0"/>
      <mass value="0.1"/>
      <inertia ixx="0.01414583" ixy="0" ixz="0" iyy="0.01414583" iyz="0" izz="0.028125"/>
    </inertial>
    <visual>
      <origin rpy="0 0 0" xyz="0 0 0"/>
      <geometry>
        <mesh filename="cylinder.stl" scale="0.75 0.75 0.1"/>
      </geometry>
      <material name="arches-blue"/>
    </visual>
    <collision>
      <origin rpy="0 0 0" xyz="0 0 0"/>
      <geometry>
        <mesh filename="cylinder.stl" scale="0.75 0.75 0.1"/>
      </geometry>
    </collision>
  </link>

  <link name="rotor4">
    <inertial>
      <origin rpy="0 0 0" xyz="0 0 0"/>
      <mass value="0.1"/>
      <inertia ixx="0.01414583" ixy="0" ixz="0" iyy="0.01414583" iyz="0" izz="0.028125"/>
    </inertial>
    <visual>
      <origin rpy="0 0 0" xyz="0 0 0"/>
      <geometry>
        <mesh filename="cylinder.stl" scale="0.75 0.75 0.1"/>
      </geometry>
      <material name="arches-blue"/>
    </visual>
    <collision>
      <origin rpy="0 0 0" xyz="0 0 0"/>
      <geometry>
        <mesh filename="cylinder.stl" scale="0.75 0.75 0.1"/>
      </geometry>
    </collision>
  </link>
  
  <link name="nametag">
    <inertial>
      <origin rpy="0 0 0" xyz="0 0 0"/>
      <mass value="0"/>
      <inertia ixx="0" ixy="0" ixz="0" iyy="0" iyz="0" izz="0"/>
    </inertial>
    <visual>
      <origin rpy="0 0 0" xyz="0 0 0"/>
      <geometry>
        <mesh filename="plane_small.obj" scale="0.5 0.5 1"/>
      </geometry>
    </visual>
  </link>
  
  <joint name="core_to_spar1" type="fixed">
    <parent link="core"/>
    <child link="spar1"/>
    <origin xyz="0 0.625 0" rpy="1.5707963267948966 0 0"/>
  </joint>
  
  <joint name="core_to_spar2" type="fixed">
    <parent link="core"/>
    <child link="spar2"/>
    <origin xyz="0.625 0 0" rpy="0 1.5707963267948966 0"/>
  </joint>
  
  <joint name="core_to_spar3" type="fixed">
    <parent link="core"/>
    <child link="spar3"/>
    <origin xyz="0 -0.625 0" rpy="1.5707963267948966 0 0"/>
  </joint>
  
  <joint name="core_to_spar4" type="fixed">
    <parent link="core"/>
    <child link="spar4"/>
    <origin xyz="-0.625 0 0" rpy="0 1.5707963267948966 0"/>
  </joint>
  
  <joint name="core_to_nametag" type="fixed">
    <parent link="core"/>
    <child link="nametag"/>
    <origin xyz="0 0 1.25" rpy="1.5707963267948966 0 1.5707963267948966"/>
  </joint>
  
  <joint name="spar1_to_rotor1" type="continuous">
    <parent link="spar1"/>
    <child link="rotor1"/>
    <origin xyz="0 0.0875 -0.375" rpy="1.5707963267948966 0 3.141592653589793"/>
    <axis xyz="0.0 0.0 1.0"/>
    <limit effort="1000.0" velocity="1000.0"/>
  </joint>
  
  <joint name="spar2_to_rotor2" type="continuous">
    <parent link="spar2"/>
    <child link="rotor2"/>
    <origin xyz="-0.0875 0 0.375" rpy="0 1.5707963267948966 3.141592653589793"/>
    <axis xyz="0.0 0.0 1.0"/>
    <limit effort="1000.0" velocity="1000.0"/>
  </joint>
  
  <joint name="spar3_to_rotor3" type="continuous">
    <parent link="spar3"/>
    <child link="rotor3"/>
    <origin xyz="0 0.0875 0.375" rpy="1.5707963267948966 0 3.141592653589793"/>
    <axis xyz="0.0 0.0 1.0"/>
    <limit effort="1000.0" velocity="1000.0"/>
  </joint>
  
  <joint name="spar4_to_rotor4" type="continuous">
    <parent link="spar4"/>
    <child link="rotor4"/>
    <origin xyz="-0.0875 0 -0.375" rpy="0 1.5707963267948966 3.141592653589793"/>
    <axis xyz="0.0 0.0 1.0"/>
    <limit effort="1000.0" velocity="1000.0"/>
  </joint>
  
</robot>
