<?xml version="1.0" ?>

<robot name="cart">
    
    <material name="industrial-blue">
        <color rgba="0.113725 0.3450980 0.654901 1" />
    </material>
    
    <material name="arches-blue">
        <color rgba="0.0 0.6235294 0.831372 1" />
    </material>
    
    <material name = "heritage-orange">
        <color rgba = "0.96078 0.50980 0.11764 1" />
    </material>
    
    
    <link name="chassis">
        <visual>
            <origin rpy="0 0 0" xyz="0 0 0"/>
            <geometry>
                <mesh filename="cube.stl" scale="1 0.5 0.25"/>
            </geometry>
            <material name = "industrial-blue"/>
        </visual>
        <collision>
            <origin rpy="0 0 0" xyz="0 0 0"/>
            <geometry>
                <mesh filename="cube.stl" scale="1 0.5 0.25"/>
            </geometry>
        </collision>
        <inertial>
            <origin rpy="0 0 0" xyz="0 0 0"/>
            <mass value="2.0"/>
            <inertia ixx="0" ixy="0" ixz="0" iyy="0" iyz="0" izz="0"/>
        </inertial>
    </link>
    
    <link name="arm">
        <visual>
            <origin rpy="0 0 0" xyz="0 0 0"/>
            <geometry>
                <mesh filename="cylinder_lower_origin.stl" scale="0.05 0.05 1.0"/>
            </geometry>
            <material name = "arches-blue"/>
        </visual>
        <collision>
            <origin rpy="0 0 0" xyz="0 0 0"/>
            <geometry>
                <mesh filename="cylinder_lower_origin.stl" scale="0.05 0.05 1.0"/>
            </geometry>
        </collision>
        <inertial>
            <origin rpy="0 0 0" xyz="0 0 1.0"/>
            <mass value="0.0"/>
            <inertia ixx="0" ixy="0" ixz="0" iyy="0" iyz="0" izz="0"/>
        </inertial>
    </link>
    
    <link name="mass">
        <visual>
            <origin rpy="0 0 0" xyz="0 0 0"/>
            <geometry>
                <mesh filename="sphere.stl" scale="0.2 0.2 0.2"/>
            </geometry>
            <material name = "arches-blue"/>
        </visual>
        <collision>
            <origin rpy="0 0 0" xyz="0 0 0"/>
            <geometry>
                <mesh filename="sphere.stl" scale="0.2 0.2 0.2"/>
            </geometry>
        </collision>
        <inertial>
            <origin rpy="0 0 0" xyz="0 0 0"/>
            <mass value="1.0"/>
            <inertia ixx="0" ixy="0" ixz="0" iyy="0" iyz="0" izz="0"/>
        </inertial>
    </link>
    
    <link name="wheel_1">
        <visual>
            <origin rpy="0 0 0" xyz="0 0 0"/>
            <geometry>
                <mesh filename="cylinder.stl" scale="0.25 0.25 0.05"/>
            </geometry>
            <material name = "heritage-orange"/>
        </visual>
        <collision>
            <origin rpy="0 0 0" xyz="0 0 0"/>
            <geometry>
                <mesh filename="cylinder.stl" scale="0.25 0.25 0.05"/>
            </geometry>
        </collision>
        <inertial>
            <origin rpy="0 0 0" xyz="0 0 0"/>
            <mass value="0.25"/>
            <inertia ixx="0.0078" ixy="0" ixz="0" iyy="0.0078" iyz="0" izz="0.0078"/>
        </inertial>
    </link>
    
    <link name="wheel_2">
        <visual>
            <origin rpy="0 0 0" xyz="0 0 0"/>
            <geometry>
                <mesh filename="cylinder.stl" scale="0.25 0.25 0.05"/>
            </geometry>
            <material name = "heritage-orange"/>
        </visual>
        <collision>
            <origin rpy="0 0 0" xyz="0 0 0"/>
            <geometry>
                <mesh filename="cylinder.stl" scale="0.25 0.25 0.05"/>
            </geometry>
        </collision>
        <inertial>
            <origin rpy="0 0 0" xyz="0 0 0"/>
            <mass value="0.25"/>
            <inertia ixx="0.0078" ixy="0" ixz="0" iyy="0.0078" iyz="0" izz="0.0078"/>
        </inertial>
    </link>
    
    <link name="wheel_3">
        <visual>
            <origin rpy="0 0 0" xyz="0 0 0"/>
            <geometry>
                <mesh filename="cylinder.stl" scale="0.25 0.25 0.05"/>
            </geometry>
            <material name = "heritage-orange"/>
        </visual>
        <collision>
            <origin rpy="0 0 0" xyz="0 0 0"/>
            <geometry>
                <mesh filename="cylinder.stl" scale="0.25 0.25 0.05"/>
            </geometry>
        </collision>
        <inertial>
            <origin rpy="0 0 0" xyz="0 0 0"/>
            <mass value="0.25"/>
            <inertia ixx="0.0078" ixy="0" ixz="0" iyy="0.0078" iyz="0" izz="0.0078"/>
        </inertial>
    </link>
    
    <link name="wheel_4">
        <visual>
            <origin rpy="0 0 0" xyz="0 0 0"/>
            <geometry>
                <mesh filename="cylinder.stl" scale="0.25 0.25 0.05"/>
            </geometry>
            <material name = "heritage-orange"/>
        </visual>
        <collision>
            <origin rpy="0 0 0" xyz="0 0 0"/>
            <geometry>
                <mesh filename="cylinder.stl" scale="0.25 0.25 0.05"/>
            </geometry>
        </collision>
        <inertial>
            <origin rpy="0 0 0" xyz="0 0 0"/>
            <mass value="0.25"/>
            <inertia ixx="0.0078" ixy="0" ixz="0" iyy="0.0078" iyz="0" izz="0.0078"/>
        </inertial>
    </link>
    
    
    <joint name="chassis_to_wheel_1" type="continuous">
        <parent link = "chassis" />
        <child link = "wheel_1" />
        <origin rpy="1.5707963267948966 0 0" xyz = "0.375 -0.275 -0.125" />
        <axis xyz = "0 0 1" />
    </joint>

    <joint name="chassis_to_wheel_2" type="continuous">
        <parent link = "chassis" />
        <child link = "wheel_2" />
        <origin rpy="1.5707963267948966 0 0" xyz = "-0.375 -0.275 -0.125" />
        <axis xyz = "0 0 1" />
    </joint>
    
    <joint name="chassis_to_wheel_3" type="continuous">
        <parent link = "chassis" />
        <child link = "wheel_3" />
        <origin rpy="1.5707963267948966 0 0" xyz = "-0.375 0.275 -0.125" />
        <axis xyz = "0 0 1" />
    </joint>
    
    <joint name="chassis_to_wheel_4" type="continuous">
        <parent link = "chassis" />
        <child link = "wheel_4" />
        <origin rpy="1.5707963267948966 0 0" xyz = "0.375 0.275 -0.125" />
        <axis xyz = "0 0 1" />
    </joint>
    
    <joint name="chassis_to_arm" type="continuous">
        <parent link = "chassis" />
        <child link = "arm" />
        <origin rpy="0 0 0" xyz = "0 0 0.125" />
        <axis xyz = "0 -1 0" />
    </joint>
    
    <joint name="arm_to_mass" type="fixed">
        <parent link = "arm" />
        <child link = "mass" />
        <origin rpy="0 0 0" xyz = "0 0 1.0" />
    </joint>

</robot>
