<?xml version="1.0" ?>
<robot name="platform">

  <material name="industrial-blue">
    <color rgba="0.11372549019607843 0.34509803921568627 0.6549019607843137 1" />
  </material>

  <material name="arches-blue">
    <color rgba="0.0 0.6235294117647059 0.8313725490196079 1" />
  </material>

  <material name = "heritage-orange">
    <color rgba = "0.96078431 0.50980392 0.11764706 1" />
  </material>

  <link name="world"/>

  <link name="outer">
    <visual>
      <origin rpy="0 0 0" xyz="0 0 0"/>
      <geometry>
  			<mesh filename="cmg_outer.stl" scale="1.0 1.0 1.0"/>
      </geometry>
      <material name = "industrial-blue"/>
    </visual>
    <collision>
      <origin rpy="0 0 0" xyz="0 0 0"/>
      <geometry>
  			<mesh filename="cmg_outer.stl" scale="1.0 1.0 1.0"/>
      </geometry>
    </collision>
    <inertial>
      <origin rpy="0 0 0" xyz="0 0 0"/>
      <mass value="1.0"/>
      <inertia ixx="0.25" ixy="0" ixz="0" iyy="0.25" iyz="0" izz="0.5"/>
    </inertial>
  </link>

  <link name="inner">
    <visual>
      <origin rpy="0 0 0" xyz="0 0 0"/>
      <geometry>
  			<mesh filename="cmg_inner.stl" scale="1.0 1.0 1.0"/>
      </geometry>
      <material name = "arches-blue"/>
    </visual>
    <collision>
      <origin rpy="0 0 0" xyz="0 0 0"/>
      <geometry>
  			<mesh filename="cmg_inner.stl" scale="1.0 1.0 1.0"/>
      </geometry>
    </collision>
    <inertial>
      <origin rpy="0 0 0" xyz="0 0 0"/>
      <mass value="0.01"/>
      <inertia ixx="0.001" ixy="0" ixz="0" iyy="0.001" iyz="0" izz="0.001"/>
    </inertial>
  </link>

  <link name="wheel">
    <visual>
      <origin rpy="0 0 0" xyz="0 0 0"/>
      <geometry>
  			<mesh filename="cmg_wheel.stl" scale="1.0 1.0 1.0"/>
      </geometry>
      <material name = "heritage-orange"/>
    </visual>
    <collision>
      <origin rpy="0 0 0" xyz="0 0 0"/>
      <geometry>
  			<mesh filename="cmg_wheel.stl" scale="1.0 1.0 1.0"/>
      </geometry>
    </collision>
    <inertial>
      <origin rpy="0 0 0" xyz="0 0 0"/>
      <mass value="0.1"/>
      <inertia ixx="0.01" ixy="0" ixz="0" iyy="0.01" iyz="0" izz="0.01"/>
    </inertial>
  </link>

  <link name="spar">
    <visual>
      <origin rpy="0 0 0" xyz="0 0 0"/>
      <geometry>
  			<mesh filename="cmg_spar.stl" scale="1.0 1.0 1.0"/>
      </geometry>
      <material name = "industrial-blue"/>
    </visual>
    <collision>
      <origin rpy="0 0 0" xyz="0 0 0"/>
      <geometry>
  			<mesh filename="cmg_spar.stl" scale="1.0 1.0 1.0"/>
      </geometry>
    </collision>
    <inertial>
      <origin rpy="0 0 0" xyz="0 0 0"/>
      <mass value="0.0"/>
      <inertia ixx="0.0" ixy="0" ixz="0" iyy="0.0" iyz="0" izz="0.0"/>
    </inertial>
  </link>

  <link name="mass">
    <visual>
      <origin rpy="0 0 0" xyz="0 0 0"/>
      <geometry>
  			<mesh filename="cmg_mass.stl" scale="1.0 1.0 1.0"/>
      </geometry>
      <material name = "industrial-blue"/>
    </visual>
    <collision>
      <origin rpy="0 0 0" xyz="0 0 0"/>
      <geometry>
  			<mesh filename="cmg_mass.stl" scale="1.0 1.0 1.0"/>
      </geometry>
    </collision>
    <inertial>
      <origin rpy="0 0 0" xyz="0 0 0"/>
      <mass value="1."/>
      <inertia ixx="0.01" ixy="0" ixz="0" iyy="0.01" iyz="0" izz="0.01"/>
    </inertial>
  </link>

  <joint name="world_to_outer" type="continuous">
		<parent link = "world" />
		<child link = "outer" />
		<origin xyz = "0 0 0" />
		<axis xyz = "0 1 0" />
		<limit effort="1000" velocity="1000"/>
	</joint>

  <joint name="outer_to_inner" type="continuous">
		<parent link = "outer" />
		<child link = "inner" />
		<origin xyz = "0 0 0" />
		<axis xyz = "1 0 0" />
		<limit effort="1000" velocity="1000"/>
	</joint>

  <joint name="inner_to_wheel" type="continuous">
		<parent link = "inner" />
		<child link = "wheel" />
		<origin xyz = "0 0 0" />
		<axis xyz = "0 0 1" />
		<limit effort="1000" velocity="1000"/>
	</joint>

  <joint name="outer_to_spar" type="fixed">
		<parent link = "outer" />
		<child link = "spar" />
		<origin xyz = "1.5 0 0" />
	</joint>

  <joint name="spar_to_mass" type="fixed">
		<parent link = "spar" />
		<child link = "mass" />
		<origin xyz = "0.5 0 0" />
	</joint>



</robot>
