<?xml version="1.0" ?>
<robot name="CMG">

    <material name="industrial-blue">
        <color rgba="0.1137254 0.345098039 0.654901960 1" />
    </material>
    
    <material name="arches-blue">
        <color rgba="0.0 0.623529411 0.831372 1" />
    </material>
    
    <material name = "heritage-orange">
        <color rgba = "0.96078431 0.50980392 0.11764706 1" />
    </material>
    
    
    <link name="world"/>
    
    <link name="frame">
        <visual>
            <origin rpy="0 0 0" xyz="0 0 0"/>
            <geometry>
                <mesh filename="cmg_outer.stl" scale="1.0 1.0 1.0"/>
            </geometry>
            <material name = "industrial-blue"/>
        </visual>
        <collision>
            <origin rpy="0 0 0" xyz="0 0 0"/>
            <geometry>
                <mesh filename="cmg_outer.stl" scale="1.0 1.0 1.0"/>
            </geometry>
        </collision>
        <inertial>
            <origin rpy="0 0 0" xyz="0 0 0"/>
            <mass value="1.0"/>
            <inertia ixx="0.25" ixy="0" ixz="0" iyy="0.25" iyz="0" izz="0.5"/>
        </inertial>
    </link>
    
    <link name="cage">
        <visual>
            <origin rpy="0 0 0" xyz="0 0 0"/>
            <geometry>
                <mesh filename="cmg_inner.stl" scale="1.0 1.0 1.0"/>
            </geometry>
            <material name = "arches-blue"/>
        </visual>
        <collision>
            <origin rpy="0 0 0" xyz="0 0 0"/>
            <geometry>
                <mesh filename="cmg_inner.stl" scale="1.0 1.0 1.0"/>
            </geometry>
        </collision>
        <inertial>
            <origin rpy="0 0 0" xyz="0 0 0"/>
            <mass value="0.01"/>
            <inertia ixx="0.001" ixy="0" ixz="0" iyy="0.001" iyz="0" izz="0.001"/>
        </inertial>
    </link>
    
    <link name="wheel">
        <visual>
            <origin rpy="0 0 0" xyz="0 0 0"/>
            <geometry>
                <mesh filename="cmg_wheel.stl" scale="1.0 1.0 1.0"/>
            </geometry>
            <material name = "heritage-orange"/>
        </visual>
        <collision>
            <origin rpy="0 0 0" xyz="0 0 0"/>
            <geometry>
                <mesh filename="cmg_wheel.stl" scale="1.0 1.0 1.0"/>
            </geometry>
        </collision>
        <inertial>
            <origin rpy="0 0 0" xyz="0 0 0"/>
            <mass value="0.1"/>
            <inertia ixx="0.01" ixy="0" ixz="0" iyy="0.01" iyz="0" izz="0.01"/>
        </inertial>
    </link>
    
    <link name="spar">
        <visual>
            <origin rpy="0 0 0" xyz="0 0 0"/>
            <geometry>
                <mesh filename="cmg_spar.stl" scale="1.0 1.0 1.0"/>
            </geometry>
            <material name = "industrial-blue"/>
        </visual>
        <collision>
            <origin rpy="0 0 0" xyz="0 0 0"/>
            <geometry>
                <mesh filename="cmg_spar.stl" scale="1.0 1.0 1.0"/>
            </geometry>
        </collision>
        <inertial>
            <origin rpy="0 0 0" xyz="0 0 0"/>
            <mass value="0.0"/>
            <inertia ixx="0.0" ixy="0" ixz="0" iyy="0.0" iyz="0" izz="0.0"/>
        </inertial>
    </link>
    
    <link name="mass">
        <visual>
            <origin rpy="0 0 0" xyz="0 0 0"/>
            <geometry>
                <mesh filename="cmg_mass.stl" scale="1.0 1.0 1.0"/>
            </geometry>
            <material name = "industrial-blue"/>
        </visual>
        <collision>
            <origin rpy="0 0 0" xyz="0 0 0"/>
            <geometry>
                <mesh filename="cmg_mass.stl" scale="1.0 1.0 1.0"/>
            </geometry>
        </collision>
        <inertial>
            <origin rpy="0 0 0" xyz="0 0 0"/>
            <mass value="1."/>
            <inertia ixx="0.01" ixy="0" ixz="0" iyy="0.01" iyz="0" izz="0.01"/>
        </inertial>
    </link>
    
    
    <joint name="world_to_frame" type="continuous">
        <parent link = "world" />
        <child link = "frame" />
        <origin xyz = "0 0 0" />
        <axis xyz = "0 1 0" />
    </joint>
    
    <joint name="frame_to_cage" type="continuous">
        <parent link = "frame" />
        <child link = "cage" />
        <origin xyz = "0 0 0" />
        <axis xyz = "1 0 0" />
    </joint>
    
    <joint name="cage_to_wheel" type="continuous">
        <parent link = "cage" />
        <child link = "wheel" />
        <origin xyz = "0 0 0" />
        <axis xyz = "0 0 1" />
    </joint>
    
    <joint name="frame_to_spar" type="fixed">
        <parent link = "frame" />
        <child link = "spar" />
        <origin xyz = "1.5 0 0" />
    </joint>
    
    <joint name="spar_to_mass" type="fixed">
        <parent link = "spar" />
        <child link = "mass" />
        <origin xyz = "0.5 0 0" />
    </joint>

</robot>
