<?xml version="1.0" ?>
<robot name="spacecraft">

  <material name="industrial-blue">
    <color rgba="0.11372549019607843 0.34509803921568627 0.6549019607843137 1" />
  </material>

  <material name="arches-blue">
    <color rgba="0.0 0.6235294117647059 0.8313725490196079 1" />
  </material>

  <material name = "heritage-orange">
    <color rgba = "0.96078431 0.50980392 0.11764706 1" />
  </material>

  <link name="world"/>

  <link name="station" concave="yes">
    <visual>
      <origin rpy="0 0 0" xyz="0 0 0"/>
      <geometry>
  			<mesh filename="station.stl" scale="1.0 1.0 3.0"/>
      </geometry>
      <material name = "arches-blue"/>
    </visual>
    <collision concave="yes">
      <origin rpy="0 0 0" xyz="0 0 0"/>
      <geometry>
  			<mesh filename="station.stl" scale="1.0 1.0 3.0"/>
      </geometry>
    </collision>
    <inertial>
      <origin rpy="0 0 0" xyz="0 0 0"/>
      <mass value="1000.0"/>
      <inertia ixx="1000.0" ixy="0" ixz="0" iyy="1000.0" iyz="0" izz="1000.0" />
    </inertial>
  </link>

  <link name="marker1">
    <visual>
      <geometry>
  			<mesh filename="disc.stl" scale="2.0 2.0 0.5"/>
      </geometry>
      <material name = "arches-blue"/>
    </visual>
    <collision>
      <geometry>
  			<mesh filename="disc.stl" scale="2.0 2.0 0.5"/>
      </geometry>
    </collision>
    <inertial>
      <mass value="1.0"/>
      <inertia ixx="0.0" ixy="0" ixz="0" iyy="0.0" iyz="0" izz="0.0" />
    </inertial>
  </link>

  <link name="marker2">
    <visual>
      <geometry>
  			<mesh filename="disc.stl" scale="2.0 2.0 0.5"/>
      </geometry>
      <material name = "arches-blue"/>
    </visual>
    <collision>
      <geometry>
  			<mesh filename="disc.stl" scale="2.0 2.0 0.5"/>
      </geometry>
    </collision>
    <inertial>
      <mass value="1.0"/>
      <inertia ixx="0.0" ixy="0" ixz="0" iyy="0.0" iyz="0" izz="0.0" />
    </inertial>
  </link>

  <link name="marker3">
    <visual>
      <geometry>
  			<mesh filename="disc.stl" scale="2.0 2.0 0.5"/>
      </geometry>
      <material name = "arches-blue"/>
    </visual>
    <collision>
      <geometry>
  			<mesh filename="disc.stl" scale="2.0 2.0 0.5"/>
      </geometry>
    </collision>
    <inertial>
      <mass value="1.0"/>
      <inertia ixx="0.0" ixy="0" ixz="0" iyy="0.0" iyz="0" izz="0.0" />
    </inertial>
  </link>

  <link name="marker4">
    <visual>
      <geometry>
  			<mesh filename="disc.stl" scale="2.0 2.0 0.5"/>
      </geometry>
      <material name = "arches-blue"/>
    </visual>
    <collision>
      <geometry>
  			<mesh filename="disc.stl" scale="2.0 2.0 0.5"/>
      </geometry>
    </collision>
    <inertial>
      <mass value="1.0"/>
      <inertia ixx="0.0" ixy="0" ixz="0" iyy="0.0" iyz="0" izz="0.0" />
    </inertial>
  </link>

  <joint name="world_to_station" type="continuous">
		<parent link = "world" />
		<child link = "station" />
		<origin xyz = "0 0 0" />
		<axis xyz = "0 0 1" />
		<limit effort="1000" velocity="1000"/>
	</joint>

  <joint name="station_to_marker1" type="fixed">
		<parent link="station" />
		<child link="marker1" />
		<origin xyz="0 -20 -3.25" />
	</joint>

  <joint name="station_to_marker2" type="fixed">
		<parent link="station" />
		<child link="marker2" />
		<origin xyz="20 0 -3.25" />
	</joint>

  <joint name="station_to_marker3" type="fixed">
		<parent link="station" />
		<child link="marker3" />
		<origin xyz="0 20 -3.25" />
	</joint>

  <joint name="station_to_marker4" type="fixed">
		<parent link="station" />
		<child link="marker4" />
		<origin xyz="-20 0 -3.25" />
	</joint>

  <link name="bumplink40">
    <visual>
      <geometry>
        <mesh filename="disc.stl" scale="3.000 3.000 0.030"/>
      </geometry>
      <material name="heritage-orange"/>
    </visual>
    <collision>
      <geometry>
        <mesh filename="disc.stl" scale="3.000 3.000 0.030"/>
      </geometry>
    </collision>
    <inertial>
      <mass value="1.0"/>
      <inertia ixx="0" ixy="0" ixz="0" iyy="0" iyz="0" izz="0"/>
    </inertial>
  </link>
  <joint name="bumpjoint40" type="fixed">
    <parent link="station"/>
    <child link="bumplink40"/>
    <origin xyz="0.000 -20.000 0.000" rpy="1.571 0.000 0.000"/>
  </joint>
</robot>
