<?xml version="1.0" ?>
<robot name="target">

  <material name="steel">
    <color rgba="0.75 0.75 0.75 1"/>
  </material>
  
  <link name="world"/>
  
  <link name="arrow">
    <visual>
      <origin rpy="0 0 0" xyz="0 0 0"/>
      <geometry>
  			<mesh filename="arrow_lin.stl" scale="1.25 0.1 0.75"/>
      </geometry>
      <material name = "steel"/>
    </visual>
    <inertial>
      <origin rpy="0 0 0" xyz="0 0 0"/>
      <mass value="0"/>
      <inertia ixx="0" ixy="0" ixz="0" iyy="0" iyz="0" izz="0"/>
    </inertial>
  </link>
  
<joint name="world_to_arrow" type="continuous">
		<parent link = "world" />
		<child link = "arrow" />
		<origin xyz = "0 0 0.0" rpy="1.5707963267948966 0 0"/>
		<axis xyz = "0 1 0" />
  </joint>

</robot>