<?xml version="1.0" ?>
<robot name="gyro">

    <material name="industrial">
        <color rgba="0.1137254 0.345098039 0.654901960 1" />
    </material>
    
    <material name="arches">
        <color rgba="0.0 0.623529411 0.831372 1" />
    </material>
    
    <material name = "heritage">
        <color rgba = "0.96078431 0.50980392 0.11764706 1" />
    </material>
    
    <link name="core">
        <visual>
            <origin rpy="0 0 0" xyz="0 0 0"/>
            <geometry>
                <mesh filename="core.stl" scale="0.1 0.1 0.1"/>
            </geometry>
            <material name = "heritage"/>
        </visual>
        <inertial>
            <origin rpy="0 0 0" xyz="0 0 0"/>
            <mass value="1.0"/>
            <inertia ixx="0.134" ixy="0" ixz="0" iyy="0.134" iyz="0" izz="0.101"/>
        </inertial>
    </link>
        
    <link name="r1" concave="yes">
        <visual>
            <origin rpy="0 0 0" xyz="0 0 0"/>
            <geometry>
                <mesh filename="ring.stl" scale="0.1 0.1 0.1"/>
            </geometry>
            <material name = "arches"/>
        </visual>
        <inertial>
            <origin rpy="0 0 0" xyz="0 0 0"/>
            <mass value="0.001"/>
            <inertia ixx="0.0018" ixy="0" ixz="0" iyy="0.0018" iyz="0" izz="0.0036"/>
        </inertial>
    </link>

    <link name="r2" concave="yes">
        <visual>
            <origin rpy="0 0 0" xyz="0 0 0"/>
            <geometry>
                <mesh filename="ring.stl" scale="0.14 0.14 0.14"/>
            </geometry>
            <material name = "arches"/>
        </visual>
        <inertial>
            <origin rpy="0 0 0" xyz="0 0 0"/>
            <mass value="0.014"/>
            <inertia ixx="0.0050" ixy="0" ixz="0" iyy="0.0050" iyz="0" izz="0.0099"/>
        </inertial>
    </link>

    <link name="outer" concave="yes">
        <visual>
            <origin rpy="0 1.571 0" xyz="0 0 0"/>
            <geometry>
                <mesh filename="outer.stl" scale="0.1 0.1 0.1"/>
            </geometry>
            <material name = "arches"/>
        </visual>
        <inertial>
            <origin rpy="0 1.571 0" xyz="0 0 0"/>
            <mass value="0.020"/>
            <inertia ixx="0.0233" ixy="0" ixz="0" iyy="0.0117" iyz="0" izz="0.0117"/>
        </inertial>
    </link>

    <link name="base">
        <visual>
            <origin rpy="0 0 0" xyz="0 0 0"/>
            <geometry>
                <mesh filename="cylinder.stl" scale="1 1 0.1"/>
            </geometry>
            <material name = "industrial"/>
        </visual>
        <inertial>
            <origin rpy="0 0 0" xyz="0 0 0"/>
            <mass value="0"/>
            <inertia ixx="0" ixy="0" ixz="0" iyy="0" iyz="0" izz="0"/>
        </inertial>
    </link>

    <joint name="base_to_outer" type="continuous">
        <parent link = "base" />
        <child link = "outer" />
        <origin rpy="0 0 0" xyz = "0 0 1.6" />
        <axis xyz = "0 0 1" />
    </joint>

    <joint name="outer_to_r2" type="continuous">
        <parent link = "outer" />
        <child link = "r2" />
        <origin rpy="0 0 0" xyz = "0 0 0" />
        <axis xyz = "0 1 0" />
    </joint>

    <joint name="r2_to_r1" type="continuous">
        <parent link = "r2" />
        <child link = "r1" />
        <origin rpy="0 1.571 1.571" xyz = "0 0 0" />
        <axis xyz = "0 1 0" />
    </joint>

    <joint name="r1_to_core" type="continuous">
        <parent link = "r1" />
        <child link = "core" />
        <origin rpy="0 1.571 0" xyz = "0 0 0" />
        <axis xyz = "0 0 1" />
    </joint>

</robot>
