<?xml version="1.0" ?>
<robot name="spacecraft">
  <material name="industrial-blue">
    <color rgba="0.11372549019607843 0.34509803921568627 0.6549019607843137 1.0"/>
  </material>
  <material name="arches-blue">
    <color rgba="0.0 0.6235294117647059 0.8313725490196079 1.0"/>
  </material>
  <material name="heritage-orange">
    <color rgba="0.96078431 0.50980392 0.11764706 1.0"/>
  </material>
  <link name="bus" concave="yes">
    <visual>
      <geometry>
        <mesh filename="spacecraft.stl" scale="1.0 1.0 1.0"/>
      </geometry>
      <material name="industrial-blue"/>
    </visual>
    <collision concave="yes">
      <geometry>
        <mesh filename="spacecraft.stl" scale="1.0 1.0 1.0"/>
      </geometry>
    </collision>
    <inertial>
      <origin rpy="0.0 0.0 0.0" xyz="0.0 0.0 0.0"/>
      <mass value="6.0"/>
      <inertia ixx="10.0" ixy="0.0" ixz="0.0" iyy="10.0" iyz="0.0" izz="16.0"/>
    </inertial>
  </link>
  <link name="wheel_1" concave="yes">
    <visual>
      <geometry>
        <mesh filename="rw1.stl" scale="0.5 0.5 0.2"/>
      </geometry>
      <material name="heritage-orange"/>
    </visual>
    <collision concave="yes">
      <geometry>
        <mesh filename="rw1.stl" scale="0.5 0.5 0.2"/>
      </geometry>
    </collision>
    <inertial>
      <origin rpy="0.0 0.0 0.0" xyz="0.0 0.0 0.0"/>
      <mass value="1.0"/>
      <inertia ixx="0.075" ixy="0.0" ixz="0.0" iyy="0.075" iyz="0.0" izz="0.125"/>
    </inertial>
  </link>
  <link name="wheel_2" concave="yes">
    <visual>
      <geometry>
        <mesh filename="rw2.stl" scale="0.5 0.5 0.2"/>
      </geometry>
      <material name="heritage-orange"/>
    </visual>
    <collision concave="yes">
      <geometry>
        <mesh filename="rw2.stl" scale="0.5 0.5 0.2"/>
      </geometry>
    </collision>
    <inertial>
      <origin rpy="0.0 0.0 0.0" xyz="0.0 0.0 0.0"/>
      <mass value="1.0"/>
      <inertia ixx="0.075" ixy="0.0" ixz="0.0" iyy="0.075" iyz="0.0" izz="0.125"/>
    </inertial>
  </link>
  <link name="wheel_3" concave="yes">
    <visual>
      <geometry>
        <mesh filename="rw3.stl" scale="0.5 0.5 0.2"/>
      </geometry>
      <material name="heritage-orange"/>
    </visual>
    <collision concave="yes">
      <geometry>
        <mesh filename="rw3.stl" scale="0.5 0.5 0.2"/>
      </geometry>
    </collision>
    <inertial>
      <origin rpy="0.0 0.0 0.0" xyz="0.0 0.0 0.0"/>
      <mass value="1.0"/>
      <inertia ixx="0.075" ixy="0.0" ixz="0.0" iyy="0.075" iyz="0.0" izz="0.125"/>
    </inertial>
  </link>
  <link name="wheel_4" concave="yes">
    <visual>
      <geometry>
        <mesh filename="rw4.stl" scale="0.5 0.5 0.2"/>
      </geometry>
      <material name="heritage-orange"/>
    </visual>
    <collision concave="yes">
      <geometry>
        <mesh filename="rw4.stl" scale="0.5 0.5 0.2"/>
      </geometry>
    </collision>
    <inertial>
      <origin rpy="0.0 0.0 0.0" xyz="0.0 0.0 0.0"/>
      <mass value="1.0"/>
      <inertia ixx="0.075" ixy="0.0" ixz="0.0" iyy="0.075" iyz="0.0" izz="0.125"/>
    </inertial>
  </link>
  <joint name="bus_to_wheel_1" type="continuous">
    <parent link="bus"/>
    <child link="wheel_1"/>
    <origin xyz="1.5556349186104048 1.5556349186104048 0.0" rpy="1.5707963267948966 0.0 2.356194490192345"/>
    <axis xyz="0.0 0.0 1.0"/>
    <limit effort="1000.0" velocity="1000.0"/>
  </joint>
  <joint name="bus_to_wheel_2" type="continuous">
    <parent link="bus"/>
    <child link="wheel_2"/>
    <origin xyz="-1.5556349186104046 1.5556349186104048 0.0" rpy="1.5707963267948966 0.0 3.9269908169872414"/>
    <axis xyz="0.0 0.0 1.0"/>
    <limit effort="1000.0" velocity="1000.0"/>
  </joint>
  <joint name="bus_to_wheel_3" type="continuous">
    <parent link="bus"/>
    <child link="wheel_3"/>
    <origin xyz="-1.555634918610405 -1.5556349186104046 0.0" rpy="1.5707963267948966 0.0 5.497787143782138"/>
    <axis xyz="0.0 0.0 1.0"/>
    <limit effort="1000.0" velocity="1000.0"/>
  </joint>
  <joint name="bus_to_wheel_4" type="continuous">
    <parent link="bus"/>
    <child link="wheel_4"/>
    <origin xyz="1.5556349186104044 -1.555634918610405 0.0" rpy="1.5707963267948966 0.0 7.0685834705770345"/>
    <axis xyz="0.0 0.0 1.0"/>
    <limit effort="1000.0" velocity="1000.0"/>
  </joint>
</robot>
