<?xml version="1.0" ?>
<robot name="CMG">

    <material name="industrial">
        <color rgba="0.1137254 0.345098039 0.654901960 1" />
    </material>
    
    <material name="arches">
        <color rgba="0.0 0.623529411 0.831372 1" />
    </material>
    
    <material name = "heritage">
        <color rgba = "0.96078431 0.50980392 0.11764706 1" />
    </material>
    
    
    <link name="wall">
        <visual>
            <origin rpy="0 0 0" xyz="0 0 0"/>
            <geometry>
                <mesh filename="plane_big.obj" scale="1.0 1.0 1.0"/>
            </geometry>
            <material name = "industrial"/>
        </visual>
        <inertial>
            <origin rpy="0 0 0" xyz="0 0 0"/>
            <mass value="0"/>
            <inertia ixx="0" ixy="0" ixz="0" iyy="0" iyz="0" izz="0"/>
        </inertial>
    </link>
        
    <link name="frame_axle">
        <visual>
            <origin rpy="0 0 0" xyz="0 0 0"/>
            <geometry>
                <mesh filename="cylinder.stl" scale="0.125 0.125 0.25"/>
            </geometry>
            <material name = "industrial"/>
        </visual>
        <inertial>
            <origin rpy="0 0 0" xyz="0 0 0"/>
            <mass value="0"/>
            <inertia ixx="0" ixy="0" ixz="0" iyy="0" iyz="0" izz="0"/>
        </inertial>
    </link>
    
    <link name="frame1">
        <visual>
            <origin rpy="0 0 0" xyz="0 0 0"/>
            <geometry>
                <mesh filename="cube.stl" scale="0.375 0.075 1.0"/>
            </geometry>
            <material name = "industrial"/>
        </visual>
        <inertial>
            <origin rpy="0 0 0" xyz="0 0 0"/>
            <mass value="0"/>
            <inertia ixx="0" ixy="0" ixz="0" iyy="0" iyz="0" izz="0"/>
        </inertial>
    </link>
    
    <link name="frame2">
        <visual>
            <origin rpy="0 0 0" xyz="0 0 0"/>
            <geometry>
                <mesh filename="cube.stl" scale="0.375 0.075 1.0"/>
            </geometry>
            <material name = "industrial"/>
        </visual>
        <inertial>
            <origin rpy="0 0 0" xyz="0 0 0"/>
            <mass value="0"/>
            <inertia ixx="0" ixy="0" ixz="0" iyy="0" iyz="0" izz="0"/>
        </inertial>
    </link>
    
    <link name="frame3">
        <visual>
            <origin rpy="0 0 0" xyz="0 0 0"/>
            <geometry>
                <mesh filename="cube.stl" scale="0.375 0.075 1.0"/>
            </geometry>
            <material name = "industrial"/>
        </visual>
        <inertial>
            <origin rpy="0 0 0" xyz="0 0 0"/>
            <mass value="0"/>
            <inertia ixx="0" ixy="0" ixz="0" iyy="0" iyz="0" izz="0"/>
        </inertial>
    </link>
    
    <link name="frame4">
        <visual>
            <origin rpy="0 0 0" xyz="0 0 0"/>
            <geometry>
                <mesh filename="cube.stl" scale="0.375 0.075 1.0"/>
            </geometry>
            <material name = "industrial"/>
        </visual>
        <inertial>
            <origin rpy="0 0 0" xyz="0 0 0"/>
            <mass value="0"/>
            <inertia ixx="0" ixy="0" ixz="0" iyy="0" iyz="0" izz="0"/>
        </inertial>
    </link>
    
    <link name="cage_axle1">
        <visual>
            <origin rpy="0 0 0" xyz="0 0 0"/>
            <geometry>
                <mesh filename="cylinder.stl" scale="0.075 0.075 0.2"/>
            </geometry>
            <material name = "arches"/>
        </visual>
        <inertial>
            <origin rpy="0 0 0" xyz="0 0 0"/>
            <mass value="0"/>
            <inertia ixx="0" ixy="0" ixz="0" iyy="0" iyz="0" izz="0"/>
        </inertial>
    </link>
    
    <link name="cage_axle2">
        <visual>
            <origin rpy="0 0 0" xyz="0 0 0"/>
            <geometry>
                <mesh filename="cylinder.stl" scale="0.075 0.075 0.2"/>
            </geometry>
            <material name = "arches"/>
        </visual>
        <inertial>
            <origin rpy="0 0 0" xyz="0 0 0"/>
            <mass value="0"/>
            <inertia ixx="0" ixy="0" ixz="0" iyy="0" iyz="0" izz="0"/>
        </inertial>
    </link>
    
    <link name="cage1">
        <visual>
            <origin rpy="0 0 0" xyz="0 0 0"/>
            <geometry>
                <mesh filename="cube.stl" scale="0.16875 0.03375 0.45"/>
            </geometry>
            <material name = "arches"/>
        </visual>
        <inertial>
            <origin rpy="0 0 0" xyz="0 0 0"/>
            <mass value="0"/>
            <inertia ixx="0" ixy="0" ixz="0" iyy="0" iyz="0" izz="0"/>
        </inertial>
    </link>
    
    <link name="cage2">
        <visual>
            <origin rpy="0 0 0" xyz="0 0 0"/>
            <geometry>
                <mesh filename="cube.stl" scale="0.16875 0.03375 0.45"/>
            </geometry>
            <material name = "arches"/>
        </visual>
        <inertial>
            <origin rpy="0 0 0" xyz="0 0 0"/>
            <mass value="0"/>
            <inertia ixx="0" ixy="0" ixz="0" iyy="0" iyz="0" izz="0"/>
        </inertial>
    </link>
    
    <link name="cage3">
        <visual>
            <origin rpy="0 0 0" xyz="0 0 0"/>
            <geometry>
                <mesh filename="cube.stl" scale="0.16875 0.03375 0.45"/>
            </geometry>
            <material name = "arches"/>
        </visual>
        <inertial>
            <origin rpy="0 0 0" xyz="0 0 0"/>
            <mass value="0"/>
            <inertia ixx="0" ixy="0" ixz="0" iyy="0" iyz="0" izz="0"/>
        </inertial>
    </link>
    
    <link name="cage4">
        <visual>
            <origin rpy="0 0 0" xyz="0 0 0"/>
            <geometry>
                <mesh filename="cube.stl" scale="0.16875 0.03375 0.45"/>
            </geometry>
            <material name = "arches"/>
        </visual>
        <inertial>
            <origin rpy="0 0 0" xyz="0 0 0"/>
            <mass value="0"/>
            <inertia ixx="0" ixy="0" ixz="0" iyy="0" iyz="0" izz="0"/>
        </inertial>
    </link>
        
    <link name="wheel">
        <visual>
            <origin rpy="0 0 0" xyz="0 0 0"/>
            <geometry>
                <mesh filename="cylinder.stl" scale="0.35 0.35 0.3825"/>
            </geometry>
            <material name = "heritage"/>
        </visual>
        <inertial>
            <origin rpy="0 0 0" xyz="0 0 0"/>
            <mass value="0.5"/>
            <inertia ixx="0.03" ixy="0" ixz="0" iyy="0.03" iyz="0" izz="0.04"/>
        </inertial>
    </link>
    
    <link name="spar">
        <visual>
            <origin rpy="0 0 0" xyz="0 0 0"/>
            <geometry>
                <mesh filename="cylinder.stl" scale="0.075 0.075 1.0"/>
            </geometry>
            <material name = "industrial"/>
        </visual>
        <inertial>
            <origin rpy="0 0 0" xyz="0 0 0"/>
            <mass value="0"/>
            <inertia ixx="0" ixy="0" ixz="0" iyy="0" iyz="0" izz="0"/>
        </inertial>
    </link>
    
    <link name="mass">
        <visual>
            <origin rpy="0 0 0" xyz="0 0 0"/>
            <geometry>
                <mesh filename="sphere.stl" scale="0.25 0.25 0.25"/>
            </geometry>
            <material name = "industrial"/>
        </visual>
        <inertial>
            <origin rpy="0 0 0" xyz="0 0 0"/>
            <mass value="1.0"/>
            <inertia ixx="0" ixy="0" ixz="0" iyy="0" iyz="0" izz="0"/>
        </inertial>
    </link>
        
    
    <joint name="wall_to_frame_axle" type="continuous">
        <parent link = "wall" />
        <child link = "frame_axle" />
        <origin rpy="0 0 0" xyz = "0 0 0.125" />
        <axis xyz = "0 0 1" />
    </joint>
    
    <joint name="frame_axle_to_frame" type="fixed">
        <parent link = "frame_axle" />
        <child link = "frame1" />
        <origin rpy="1.5707963267948966 0 0" xyz = "0 0 0.1625" />
    </joint>
    
    <joint name="frame1_to_frame2" type="fixed">
        <parent link = "frame1" />
        <child link = "frame2" />
        <origin rpy="1.5707963267948966 0 0" xyz = "0 0.4625 0.4625" />
    </joint>
    
    <joint name="frame1_to_frame3" type="fixed">
        <parent link = "frame1" />
        <child link = "frame3" />
        <origin rpy="1.5707963267948966 0 0" xyz = "0 0.4625 -0.4625" />
    </joint>
    
    <joint name="frame1_to_frame4" type="fixed">
        <parent link = "frame1" />
        <child link = "frame4" />
        <origin rpy="0 0 0" xyz = "0 0.925 0" />
    </joint>
    
    <joint name="frame_to_cage_axle" type="continuous">
        <parent link = "frame2" />
        <child link = "cage_axle1" />
        <origin rpy="-1.5707963267948966 0 0" xyz = "0 -0.1375 0" />
        <axis xyz = "0 0 1" />
    </joint>
    
    <joint name="cage_axle_to_cage" type="fixed">
        <parent link = "cage_axle1" />
        <child link = "cage1" />
        <origin rpy="1.5707963267948966 0 1.5707963267948966" xyz = "0 0 -0.116875" />
    </joint>
    
    <joint name="cage1_to_cage2" type="fixed">
        <parent link = "cage1" />
        <child link = "cage2" />
        <origin rpy="1.5707963267948966 0 0" xyz = "0 -0.208125 0.208125" />
    </joint>
    
    <joint name="cage1_to_cage3" type="fixed">
        <parent link = "cage1" />
        <child link = "cage3" />
        <origin rpy="1.5707963267948966 0 0" xyz = "0 -0.208125 -0.208125" />
    </joint>
    
    <joint name="cage1_to_cage4" type="fixed">
        <parent link = "cage1" />
        <child link = "cage4" />
        <origin rpy="0 0 0" xyz = "0 -0.416250 0" />
    </joint>
    
    <joint name="cage_to_cage_axle2" type="fixed">
        <parent link = "cage4" />
        <child link = "cage_axle2" />
        <origin rpy="1.5707963267948966 0 0" xyz = "0 -0.116875 0" />
    </joint>
    
    <joint name="cage_to_wheel" type="continuous">
        <parent link = "cage2" />
        <child link = "wheel" />
        <origin rpy="1.5707963267948966 0 0" xyz = "0 -0.208125 0" />
        <axis xyz = "0 0 1" />
    </joint>
    
    <joint name="frame2_to_spar" type="fixed">
        <parent link = "frame2" />
        <child link = "spar" />
        <origin rpy="1.5707963267948966 0 0" xyz = "0 0.5375 0" />
    </joint>
    
    <joint name="spar_to_mass" type="fixed">
        <parent link = "spar" />
        <child link = "mass" />
        <origin rpy="0 0 0" xyz = "0 0 -0.5" />
    </joint>

</robot>
