<?xml version="1.0" ?>
<robot name="spacecraft">

    <material name="industrial-blue">
        <color rgba="0.113725490196 0.3450980 0.65490196 1.0"/>
    </material>
    
    <material name="arches-blue">
        <color rgba="0.0 0.6235294117647059 0.8313725490196079 1.0"/>
    </material>
    
    <material name="heritage-orange">
        <color rgba="0.96078431 0.50980392 0.11764706 1.0"/>
    </material>
    
    
    <link name="bus" concave="yes">
        <visual>
            <geometry>
                <mesh filename="spacecraft.stl" scale="1.0 1.0 1.0"/>
            </geometry>
            <material name="industrial-blue"/>
        </visual>
        <collision concave="yes">
            <geometry>
                <mesh filename="spacecraft.stl" scale="1.0 1.0 1.0"/>
            </geometry>
        </collision>
        <inertial>
            <origin rpy="0.0 0.0 0.0" xyz="0.0 0.0 0.0"/>
            <mass value="6.0"/>
            <inertia ixx="10.0" ixy="0.0" ixz="0.0" iyy="10.0" iyz="0.0" izz="16.0"/>
        </inertial>
    </link>
    
    <link name="wheel_1" concave="yes">
        <visual>
            <geometry>
                <mesh filename="rw1.stl" scale="0.5 0.5 0.2"/>
            </geometry>
            <material name="heritage-orange"/>
        </visual>
        <collision concave="yes">
            <geometry>
                <mesh filename="rw1.stl" scale="0.5 0.5 0.2"/>
            </geometry>
        </collision>
        <inertial>
            <origin rpy="0.0 0.0 0.0" xyz="0.0 0.0 0.0"/>
            <mass value="1.0"/>
            <inertia ixx="0.075" ixy="0.0" ixz="0.0" iyy="0.075" iyz="0.0" izz="0.125"/>
        </inertial>
    </link>
    
    <link name="wheel_2" concave="yes">
        <visual>
            <geometry>
                <mesh filename="rw2.stl" scale="0.5 0.5 0.2"/>
            </geometry>
            <material name="heritage-orange"/>
        </visual>
        <collision concave="yes">
            <geometry>
                <mesh filename="rw2.stl" scale="0.5 0.5 0.2"/>
            </geometry>
        </collision>
        <inertial>
            <origin rpy="0.0 0.0 0.0" xyz="0.0 0.0 0.0"/>
            <mass value="1.0"/>
            <inertia ixx="0.075" ixy="0.0" ixz="0.0" iyy="0.075" iyz="0.0" izz="0.125"/>
        </inertial>
    </link>
    
    <link name="wheel_3" concave="yes">
        <visual>
            <geometry>
                <mesh filename="rw3.stl" scale="0.5 0.5 0.2"/>
            </geometry>
            <material name="heritage-orange"/>
        </visual>
        <collision concave="yes">
            <geometry>
                <mesh filename="rw3.stl" scale="0.5 0.5 0.2"/>
            </geometry>
        </collision>
        <inertial>
            <origin rpy="0.0 0.0 0.0" xyz="0.0 0.0 0.0"/>
            <mass value="1.0"/>
            <inertia ixx="0.075" ixy="0.0" ixz="0.0" iyy="0.075" iyz="0.0" izz="0.125"/>
        </inertial>
    </link>
    
    <link name="wheel_4" concave="yes">
        <visual>
            <geometry>
                <mesh filename="rw4.stl" scale="0.5 0.5 0.2"/>
            </geometry>
            <material name="heritage-orange"/>
        </visual>
        <collision concave="yes">
            <geometry>
                <mesh filename="rw4.stl" scale="0.5 0.5 0.2"/>
            </geometry>
        </collision>
        <inertial>
            <origin rpy="0.0 0.0 0.0" xyz="0.0 0.0 0.0"/>
            <mass value="1.0"/>
            <inertia ixx="0.075" ixy="0.0" ixz="0.0" iyy="0.075" iyz="0.0" izz="0.125"/>
        </inertial>
    </link>
    
    
    <joint name="bus_to_wheel_1" type="continuous">
        <parent link="bus"/>
        <child link="wheel_1"/>
        <origin xyz="0.0 0.0 2.2" rpy="0.0 0.0 1.570796"/>
        <axis xyz="0.0 0.0 1.0"/>
    </joint>
    
    <joint name="bus_to_wheel_2" type="continuous">
        <parent link="bus"/>
        <child link="wheel_2"/>
        <origin xyz="0.952628 1.65 -1.1" rpy="2.094395 0.0 2.617994"/>
        <axis xyz="0.0 0.0 1.0"/>
    </joint>
    
    <joint name="bus_to_wheel_3" type="continuous">
        <parent link="bus"/>
        <child link="wheel_3"/>
        <origin xyz="-1.905256 0.0 -1.1" rpy="2.094395 0.0 4.712389"/>
        <axis xyz="0.0 0.0 1.0"/>
    </joint>
    
    <joint name="bus_to_wheel_4" type="continuous">
        <parent link="bus"/>
        <child link="wheel_4"/>
        <origin xyz="0.952628 -1.65 -1.1" rpy="2.094395 0.0 0.523599"/>
        <axis xyz="0.0 0.0 1.0"/>
    </joint>
    
    
</robot>
